<?xml version="1.0" ?>
<!-- This URDF was automatically created by SolidWorks to URDF Exporter! Originally created by Stephen Brawner (brawner@gmail.com) 
     Commit Version: 1.6.0-4-g7f85cfe  Build Version: 1.6.7995.38578
     For more information, please see http://wiki.ros.org/sw_urdf_exporter -->
<robot
  name="tarzan" xmlns:xacro="http://ros.org/wiki/xacro">
  
  <!-- # Add this before base link -->
  <link name="dummy_link"></link>

  <link
    name="base">
    <inertial>
      <origin
        xyz="-0.000388315155439123 -0.000246415116432946 0.031353898640965"
        rpy="0 0 0" />
      <mass
        value="121.617841669888" />
      <inertia
        ixx="2.34302868736616"
        ixy="0.00879017006194074"
        ixz="-0.0428506040334107"
        iyy="8.25093215351618"
        iyz="-0.0116556489164161"
        izz="9.73837072519836" />
    </inertial>
    <visual>
      <origin
        xyz="0 0 0"
        rpy="0 0 0" />
      <geometry>
        <mesh
          filename="package://tarzan/meshes/base.STL" />
      </geometry>
      <material
        name="">
        <color
          rgba="0.792156862745098 0.819607843137255 0.933333333333333 1" />
      </material>
    </visual>
    <collision>
      <origin
        xyz="0 0 0"
        rpy="0 0 0" />
      <geometry>
        <mesh
          filename="package://tarzan/meshes/base.STL" />
      </geometry>
    </collision>
  </link>
  
  <!-- # Add this after base link -->
  <joint name="dummy_joint" type="fixed">
    <origin rpy="0 0 0" xyz="0 0 0" />
    <parent link="dummy_link"/>
    <child link="base"/>
  </joint>

  <link
    name="front_right">
    <inertial>
      <origin
        xyz="-6.78717998470191E-10 1.09086044919326E-08 0.134444489467587"
        rpy="0 0 0" />
      <mass
        value="30.6884680089216" />
      <inertia
        ixx="0.595815452910559"
        ixy="-2.25204956488811E-08"
        ixz="-1.5337779631433E-09"
        iyy="0.595815644901867"
        iyz="-4.56210336938212E-08"
        izz="0.910300957186937" />
    </inertial>
    <visual>
      <origin
        xyz="0 0 0"
        rpy="0 0 0" />
      <geometry>
        <mesh
          filename="package://tarzan/meshes/front_right.STL" />
      </geometry>
      <material
        name="">
        <color
          rgba="0.298039215686275 0.298039215686275 0.298039215686275 1" />
      </material>
    </visual>
    <collision>
      <origin
        xyz="0 0 0"
        rpy="0 0 0" />
      <geometry>
        <mesh
          filename="package://tarzan/meshes/front_right.STL" />
      </geometry>
    </collision>
  </link>
  <joint
    name="front_right_j"
    type="continuous">
    <origin
      xyz="0.26604 -0.23876 -0.09525"
      rpy="1.5794 -0.4196 -0.0049446" />
    <parent
      link="base" />
    <child
      link="front_right" />
      
    <axis
      xyz="0 0 1" />
  </joint>
  <link
    name="front_left">
    <inertial>
      <origin
        xyz="-4.33936553356773E-10 1.00053629409347E-08 0.133938019458945"
        rpy="0 0 0" />
      <mass
        value="30.6884681324061" />
      <inertia
        ixx="0.595815444469247"
        ixy="-2.48300592309292E-08"
        ixz="-2.74294234385315E-09"
        iyy="0.595815641015375"
        iyz="-4.5740529209734E-08"
        izz="0.910300946674862" />
    </inertial>
    <visual>
      <origin
        xyz="0 0 0"
        rpy="0 0 0" />
      <geometry>
        <mesh
          filename="package://tarzan/meshes/front_left.STL" />
      </geometry>
      <material
        name="">
        <color
          rgba="0.298039215686275 0.298039215686275 0.298039215686275 1" />
      </material>
    </visual>
    <collision>
      <origin
        xyz="0 0 0"
        rpy="0 0 0" />
      <geometry>
        <mesh
          filename="package://tarzan/meshes/front_left.STL" />
      </geometry>
    </collision>
  </link>
  <joint
    name="front_left_j"
    type="continuous">
    <origin
      xyz="0.266727643783791 0.23997653699215 -0.091479314618849"
      rpy="1.56237155647839 -0.362690906963914 -3.14003430832851" />
    <parent
      link="base" />
    <child
      link="front_left" />
    <axis
      xyz="0 0 1" />
  </joint>
  <link
    name="rear_left">
    <inertial>
      <origin
        xyz="-1.48962814305875E-10 1.08224411654589E-08 0.134041599980716"
        rpy="0 0 0" />
      <mass
        value="30.6884680232696" />
      <inertia
        ixx="0.59581545217311"
        ixy="-2.181218672348E-08"
        ixz="-4.16910485301347E-10"
        iyy="0.595815645336111"
        iyz="-4.60307556501621E-08"
        izz="0.910300957128926" />
    </inertial>
    <visual>
      <origin
        xyz="0 0 0"
        rpy="0 0 0" />
      <geometry>
        <mesh
          filename="package://tarzan/meshes/rear_left.STL" />
      </geometry>
      <material
        name="">
        <color
          rgba="0.298039215686275 0.298039215686275 0.298039215686275 1" />
      </material>
    </visual>
    <collision>
      <origin
        xyz="0 0 0"
        rpy="0 0 0" />
      <geometry>
        <mesh
          filename="package://tarzan/meshes/rear_left.STL" />
      </geometry>
    </collision>
  </link>
  <joint
    name="rear_left_j"
    type="continuous">
    <origin
      xyz="-0.266668894690048 0.240621830976103 -0.0896662871121348"
      rpy="-1.55052524383001 -1.17169510288349 -0.0201091297878387" />
    <parent
      link="base" />
    <child
      link="rear_left" />
    <axis
      xyz="0 0 1" />
  </joint>
  <link
    name="rear_right">
    <inertial>
      <origin
        xyz="-1.63488250715105E-10 1.14451541577409E-08 0.134621956474277"
        rpy="0 0 0" />
      <mass
        value="30.688467837621" />
      <inertia
        ixx="0.595815574018795"
        ixy="-4.15877944581755E-08"
        ixz="8.40428693131556E-09"
        iyy="0.595815669332093"
        iyz="-5.67261778435663E-09"
        izz="0.910301056514685" />
    </inertial>
    <visual>
      <origin
        xyz="0 0 0"
        rpy="0 0 0" />
      <geometry>
        <mesh
          filename="package://tarzan/meshes/rear_right.STL" />
      </geometry>
      <material
        name="">
        <color
          rgba="0.298039215686275 0.298039215686275 0.298039215686275 1" />
      </material>
    </visual>
    <collision>
      <origin
        xyz="0 0 0"
        rpy="0 0 0" />
      <geometry>
        <mesh
          filename="package://tarzan/meshes/rear_right.STL" />
      </geometry>
    </collision>
  </link>
  <joint
    name="rear_right_j"
    type="continuous">
    <origin
      xyz="-0.267353448578213 -0.237835138005729 -0.0934350258270648"
      rpy="-1.58135415755208 -0.72867400329929 -3.13599300214289" />
    <parent
      link="base" />
    <child
      link="rear_right" />
    <axis
      xyz="0 0 1" />
  </joint>
  <link
    name="walle_head">
    <inertial>
      <origin
        xyz="0.561365371191084 0.887641689012485 0.6566793484427"
        rpy="0 0 0" />
      <mass
        value="11.0701333132767" />
      <inertia
        ixx="0.0323141898509273"
        ixy="0.000918689189995389"
        ixz="-5.11394492923242E-05"
        iyy="0.0333275033032101"
        iyz="1.65339724515247E-06"
        izz="0.0323544137304436" />
    </inertial>
    <visual>
      <origin
        xyz="0 0 0"
        rpy="0 0 0" />
      <geometry>
        <mesh
          filename="package://tarzan/meshes/walle_head.STL" />
      </geometry>
      <material
        name="">
        <color
          rgba="0.792156862745098 0.819607843137255 0.933333333333333 1" />
      </material>
    </visual>
    <collision>
      <origin
        xyz="0 0 0"
        rpy="0 0 0" />
      <geometry>
        <mesh
          filename="package://tarzan/meshes/walle_head.STL" />
      </geometry>
    </collision>
  </link>
  <joint
    name="walle_head_j"
    type="fixed">
    <origin
      xyz="1.70515026961944 -0.0121736325383651 0.212448526723274"
      rpy="-0.444375979373239 0.14045100042963 2.06410361046528" />
    <parent
      link="base" />
    <child
      link="walle_head" />
    <axis
      xyz="0 0 0" />
  </joint>
  <link
    name="ur10">
    <inertial>
      <origin
        xyz="-0.00287681901700804 -0.000162361622974369 0.0183343080758503"
        rpy="0 0 0" />
      <mass
        value="0.706324319593749" />
      <inertia
        ixx="0.00114585793061116"
        ixy="-6.21874343280211E-08"
        ixz="3.53119557315341E-06"
        iyy="0.00115563795040409"
        iyz="-7.75034751904609E-06"
        izz="0.0021288958389946" />
    </inertial>
    <visual>
      <origin
        xyz="0 0 0"
        rpy="0 0 0" />
      <geometry>
        <mesh
          filename="package://tarzan/meshes/ur10.STL" />
      </geometry>
      <material
        name="">
        <color
          rgba="0.792156862745098 0.819607843137255 0.933333333333333 1" />
      </material>
    </visual>
    <collision>
      <origin
        xyz="0 0 0"
        rpy="0 0 0" />
      <geometry>
        <mesh
          filename="package://tarzan/meshes/ur10.STL" />
      </geometry>
    </collision>
  </link>
  <joint
    name="ur10_j"
    type="fixed">
    <origin
      xyz="-0.283226703332039 -0.00100073609891106 0.180406051516603"
      rpy="0 0 0" />
    <parent
      link="base" />
    <child
      link="ur10" />
    <axis
      xyz="0 0 0" />
  </joint>
  <link
    name="01">
    <inertial>
      <origin
        xyz="-0.000129690266933546 0.0106827399922714 0.0923995319867585"
        rpy="0 0 0" />
      <mass
        value="3.07353621079349" />
      <inertia
        ixx="0.0114767844399277"
        ixy="1.56443057684007E-05"
        ixz="1.58867328254487E-05"
        iyy="0.0107305809041932"
        iyz="-0.000853542638620594"
        izz="0.0101061259549641" />
    </inertial>
    <visual>
      <origin
        xyz="0 0 0"
        rpy="0 0 0" />
      <geometry>
        <mesh
          filename="package://tarzan/meshes/01.STL" />
      </geometry>
      <material
        name="">
        <color
          rgba="0.792156862745098 0.819607843137255 0.933333333333333 1" />
      </material>
    </visual>
    <collision>
      <origin
        xyz="0 0 0"
        rpy="0 0 0" />
      <geometry>
        <mesh
          filename="package://tarzan/meshes/01.STL" />
      </geometry>
    </collision>
  </link>
  <joint
    name="01j"
    type="revolute">
    <origin
      xyz="-0.00254 0 0.024064"
      rpy="0 0 0" />
    <parent
      link="ur10" />
    <child
      link="01" />
    <axis
      xyz="-0.0033894 0.0078814 -0.99996" />
    <limit
      lower="-3.14"
      upper="3.14"
      effort="1"
      velocity="0" />
  </joint>
  <link
    name="12">
    <inertial>
      <origin
        xyz="-0.00403933798877659 -0.184579089259361 0.168692913666121"
        rpy="0 0 0" />
      <mass
        value="7.37860778652606" />
      <inertia
        ixx="0.093618958303473"
        ixy="0.00102560508077754"
        ixz="3.05806623093026E-05"
        iyy="0.0172122738364342"
        iyz="0.000286423402832924"
        izz="0.0922852715202601" />
    </inertial>
    <visual>
      <origin
        xyz="0 0 0"
        rpy="0 0 0" />
      <geometry>
        <mesh
          filename="package://tarzan/meshes/12.STL" />
      </geometry>
      <material
        name="">
        <color
          rgba="0.792156862745098 0.819607843137255 0.933333333333333 1" />
      </material>
    </visual>
    <collision>
      <origin
        xyz="0 0 0"
        rpy="0 0 0" />
      <geometry>
        <mesh
          filename="package://tarzan/meshes/12.STL" />
      </geometry>
    </collision>
  </link>
  <joint
    name="12j"
    type="revolute">
    <origin
      xyz="0.00254 0 0.10802"
      rpy="-1.5708 0 0" />
    <parent
      link="01" />
    <child
      link="12" />
    <axis
      xyz="0.024882 0.0079634 -0.99966" />
    <limit
      lower="-3.14"
      upper="3.14"
      effort="1"
      velocity="0" />
  </joint>
  <link
    name="23">
    <inertial>
      <origin
        xyz="0.00695605013038159 -0.000745910743610023 -0.119252589267762"
        rpy="0 0 0" />
      <mass
        value="1.33383777507404" />
      <inertia
        ixx="0.00271427312153752"
        ixy="1.01764483797795E-05"
        ixz="0.000268693822747311"
        iyy="0.00289173075767376"
        iyz="-1.36815836110194E-05"
        izz="0.00263726996139657" />
    </inertial>
    <visual>
      <origin
        xyz="0 0 0"
        rpy="0 0 0" />
      <geometry>
        <mesh
          filename="package://tarzan/meshes/23.STL" />
      </geometry>
      <material
        name="">
        <color
          rgba="0.792156862745098 0.819607843137255 0.933333333333333 1" />
      </material>
    </visual>
    <collision>
      <origin
        xyz="0 0 0"
        rpy="0 0 0" />
      <geometry>
        <mesh
          filename="package://tarzan/meshes/23.STL" />
      </geometry>
    </collision>
  </link>
  <joint
    name="23j"
    type="fixed">
    <origin
      xyz="0.00254 -0.60699 0.04064"
      rpy="3.1416 0 1.5708" />
    <parent
      link="12" />
    <child
      link="23" />
    <axis
      xyz="0 0 0" />
  </joint>
  <link
    name="34">
    <inertial>
      <origin
        xyz="-0.201916853842532 0.00698682516623067 -0.00239486918287028"
        rpy="0 0 0" />
      <mass
        value="3.92494771754718" />
      <inertia
        ixx="0.00495218359938935"
        ixy="0.00100393089829343"
        ixz="0.000558357470659199"
        iyy="0.050575529451549"
        iyz="-1.35101992246519E-05"
        izz="0.0505340649727736" />
    </inertial>
    <visual>
      <origin
        xyz="0 0 0"
        rpy="0 0 0" />
      <geometry>
        <mesh
          filename="package://tarzan/meshes/34.STL" />
      </geometry>
      <material
        name="">
        <color
          rgba="0.792156862745098 0.819607843137255 0.933333333333333 1" />
      </material>
    </visual>
    <collision>
      <origin
        xyz="0 0 0"
        rpy="0 0 0" />
      <geometry>
        <mesh
          filename="package://tarzan/meshes/34.STL" />
      </geometry>
    </collision>
  </link>
  <joint
    name="34j"
    type="revolute">
    <origin
      xyz="0 0 0"
      rpy="0 0 0" />
    <parent
      link="23" />
    <child
      link="34" />
    <axis
      xyz="-0.0080008 -0.027654 -0.99959" />
    <limit
      lower="-3.14"
      upper="3.14"
      effort="1"
      velocity="0" />
  </joint>
  <link
    name="45">
    <inertial>
      <origin
        xyz="0.000227539945151567 -0.00816170317034381 -0.00888627452805837"
        rpy="0 0 0" />
      <mass
        value="0.72849769007602" />
      <inertia
        ixx="0.00111503947097973"
        ixy="-6.60960214988537E-07"
        ixz="1.69182369868094E-06"
        iyy="0.00103092009593852"
        iyz="9.07933921554274E-05"
        izz="0.000883757683682205" />
    </inertial>
    <visual>
      <origin
        xyz="0 0 0"
        rpy="0 0 0" />
      <geometry>
        <mesh
          filename="package://tarzan/meshes/45.STL" />
      </geometry>
      <material
        name="">
        <color
          rgba="0.792156862745098 0.819607843137255 0.933333333333333 1" />
      </material>
    </visual>
    <collision>
      <origin
        xyz="0 0 0"
        rpy="0 0 0" />
      <geometry>
        <mesh
          filename="package://tarzan/meshes/45.STL" />
      </geometry>
    </collision>
  </link>
  <joint
    name="45j"
    type="revolute">
    <origin
      xyz="-0.57404 0.015 0.0015343"
      rpy="0.0073998 0.027825 1.5491" />
    <parent
      link="34" />
    <child
      link="45" />
    <axis
      xyz="0 1 0" />
    <limit
      lower="-3.14"
      upper="3.14"
      effort="1"
      velocity="0" />
  </joint>
  <link
    name="56">
    <inertial>
      <origin
        xyz="-0.00201713270545506 -0.00942813164987086 0.0100169896786566"
        rpy="0 0 0" />
      <mass
        value="0.728501328247528" />
      <inertia
        ixx="0.00111501644965484"
        ixy="1.39114630444642E-06"
        ixz="1.01107526694737E-06"
        iyy="0.00103237997261993"
        iyz="-8.96280934412049E-05"
        izz="0.000882340838056584" />
    </inertial>
    <visual>
      <origin
        xyz="0 0 0"
        rpy="0 0 0" />
      <geometry>
        <mesh
          filename="package://tarzan/meshes/56.STL" />
      </geometry>
      <material
        name="">
        <color
          rgba="0.792156862745098 0.819607843137255 0.933333333333333 1" />
      </material>
    </visual>
    <collision>
      <origin
        xyz="0 0 0"
        rpy="0 0 0" />
      <geometry>
        <mesh
          filename="package://tarzan/meshes/56.STL" />
      </geometry>
    </collision>
  </link>
  <joint
    name="56j"
    type="revolute">
    <origin
      xyz="0.0032435 -0.00086233 -0.11653"
      rpy="-1.5788 -0.027658 0.021884" />
    <parent
      link="45" />
    <child
      link="56" />
    <axis
      xyz="-0.020664 0.99976 0.0078491" />
    <limit
      lower="-3.14"
      upper="3.14"
      effort="1"
      velocity="0" />
  </joint>
  <link
    name="67">
    <inertial>
      <origin
        xyz="0.00123982744678075 0.00833130719851138 0.010131332359845"
        rpy="0 0 0" />
      <mass
        value="0.728502495028712" />
      <inertia
        ixx="0.00111491225253058"
        ixy="-2.07388358322441E-06"
        ixz="5.66100252324822E-06"
        iyy="0.00102948947931321"
        iyz="9.19195125213603E-05"
        izz="0.000885329515752123" />
    </inertial>
    <visual>
      <origin
        xyz="0 0 0"
        rpy="0 0 0" />
      <geometry>
        <mesh
          filename="package://tarzan/meshes/67.STL" />
      </geometry>
      <material
        name="">
        <color
          rgba="0.792156862745098 0.819607843137255 0.933333333333333 1" />
      </material>
    </visual>
    <collision>
      <origin
        xyz="0 0 0"
        rpy="0 0 0" />
      <geometry>
        <mesh
          filename="package://tarzan/meshes/67.STL" />
      </geometry>
    </collision>
  </link>
  <joint
    name="67j"
    type="revolute">
    <origin
      xyz="-0.0032738 -0.0029884 0.11684"
      rpy="-1.5708 0 0" />
    <parent
      link="56" />
    <child
      link="67" />
    <axis
      xyz="0.0041161 -0.99996 -0.0077657" />
    <limit
      lower="-3.14"
      upper="3.14"
      effort="1"
      velocity="0" />
  </joint>
  <link
    name="78">
    <inertial>
      <origin
        xyz="-0.0013956559331878 0.000152032933465662 0.0115233904371586"
        rpy="0 0 0" />
      <mass
        value="0.159236547304685" />
      <inertia
        ixx="8.7749814662025E-05"
        ixy="4.04801333380738E-07"
        ixz="-1.16640611602735E-06"
        iyy="8.19414272622417E-05"
        iyz="-4.90255870702937E-07"
        izz="0.000149610319850018" />
    </inertial>
    <visual>
      <origin
        xyz="0 0 0"
        rpy="0 0 0" />
      <geometry>
        <mesh
          filename="package://tarzan/meshes/78.STL" />
      </geometry>
      <material
        name="">
        <color
          rgba="0.792156862745098 0.819607843137255 0.933333333333333 1" />
      </material>
    </visual>
    <collision>
      <origin
        xyz="0 0 0"
        rpy="0 0 0" />
      <geometry>
        <mesh
          filename="package://tarzan/meshes/78.STL" />
      </geometry>
    </collision>
  </link>
  <joint
    name="78j"
    type="revolute">
    <origin
      xyz="0 0 0.0635"
      rpy="0 0 0" />
    <parent
      link="67" />
    <child
      link="78" />
    <axis
      xyz="-0.026512 -0.0078721 0.99962" />
    <limit
      lower="-3.14"
      upper="3.14"
      effort="1"
      velocity="0" />
  </joint>

 <ros2_control name="GazeboSystem" type="system">
   <hardware>
     <plugin>gazebo_ros2_control/GazeboSystem</plugin>
   </hardware>

   <!-- # Velocity Controllers -->

   <joint name="front_right">
      <command_interface name="velocity">
          <param name="min">-1000.0</param>
          <param name="max">1000.0</param>
      </command_interface>
      <state_interface name="position"/>
      <state_interface name="velocity"/>
   </joint>
   <joint name="front_left_j">
      <command_interface name="velocity">
          <param name="min">-1000.0</param>
          <param name="max">1000.0</param>
      </command_interface>
      <state_interface name="position"/>
      <state_interface name="velocity"/>
   </joint>
   <joint name="rear_right">
      <command_interface name="velocity">
          <param name="min">-1000.0</param>
          <param name="max">1000.0</param>
      </command_interface>
      <state_interface name="position"/>
      <state_interface name="velocity"/>
   </joint>
   <joint name="rear_left_j">
      <command_interface name="velocity">
          <param name="min">-1000.0</param>
          <param name="max">1000.0</param>
      </command_interface>
      <state_interface name="position"/>
      <state_interface name="velocity"/>
   </joint>
  
 

 <!-- Position Controller -->
    <joint name="front_left_axel_joint">
        <command_interface name="position">
            <param name="min">-3.14</param>
            <param name="max">3.14</param>
        </command_interface>
        <state_interface name="position"/>
        <state_interface name="velocity"/>
    </joint>

  </ros2_control>

  <gazebo>
    <plugin filename="libgazebo_ros2_control.so" name="gazebo_ros2_control">
        <parameters>$(find tarzan)/config/control.yaml</parameters>
    </plugin>
  </gazebo>

</robot>
